<?xml version="1.0"?>
<robot xmlns:xacro="http://ros.org/wiki/xacro">

  <xacro:include filename="$(find raspicat)/urdf/common.xacro"/> 
  <xacro:include filename="$(find raspicat)/urdf/common_properties.xacro"/>
  
  <xacro:macro name="wheel" params="prefix parent *joint_origin *joint_axis">
  <joint name="${prefix}_wheel_joint" type="continuous">
    <xacro:insert_block name="joint_origin"/>
    <xacro:insert_block name="joint_axis"/>
    <parent link="${parent}"/>
    <child link="${prefix}_wheel"/>
    <limit effort="70" velocity="15"/>
    <safety_controller  k_velocity="10" />
    <dynamics damping="1.0" friction="1.0" />
  </joint>
  <link name="${prefix}_wheel">
    <visual>
      <geometry>
        <mesh filename="package://raspicat/meshes/wheel/raspberry_pi_cat_wheel_left.stl" scale="0.001 0.001 0.001"/>
      </geometry>
    </visual>
    <collision>
      <origin xyz="0 0 0.003" />
        <geometry>
          <cylinder radius="${wheel_radius}" length="${wheel_length}"/>
        </geometry>
    </collision>
      <inertial>
        <origin xyz="-0.000107 0 0.002875"/>
        <mass value="${wheel_mass}"/>
        <inertia ixx="0.000002208187" ixy="0.000000000001" iyy="0.00000218412" ixz="0.000000004787" iyz="0.000000000003" izz="0.000004078299"/>
      </inertial>
  </link>

  <link name="${prefix}_wheel">
    <visual>
      <geometry>
        <mesh filename="package://raspicat/meshes/wheel/raspberry_pi_cat_wheel_right.stl" scale="0.001 0.001 0.001"/>
      </geometry>
    </visual>
    <collision>
      <origin xyz="0 0 0.003" />
        <geometry>
          <cylinder radius="${wheel_radius}" length="${wheel_length}"/>
        </geometry>
    </collision>
      <inertial>
        <origin xyz="-0.000107 0 0.002875"/>
        <mass value="${wheel_mass}"/>
        <inertia ixx="0.000002208187" ixy="0.000000000001" iyy="0.00000218412" ixz="0.000000004787" iyz="0.000000000003" izz="0.000004078299"/>
      </inertial>
  </link>
  </xacro:macro>
</robot>